<?xml version="1.0" ?>
<sdf version="1.6">
  <world name="default">
    <physics name="1ms" type="ignored">
      <max_step_size>0.001</max_step_size>
      <real_time_factor>1.0</real_time_factor>
    </physics>
    <light type="directional" name="sun">
      <cast_shadows>true</cast_shadows>
      <pose>0 0 10 0 0 0</pose>
      <diffuse>0.8 0.8 0.8 1</diffuse>
      <specular>0.2 0.2 0.2 1</specular>
      <attenuation>
        <range>1000</range>
        <constant>0.9</constant>
        <linear>0.01</linear>
        <quadratic>0.001</quadratic>
      </attenuation>
      <direction>-0.5 0.1 -0.9</direction>
    </light>
    <model name="ground_plane">
      <static>true</static>
      <link name="link">
        <collision name="collision">
          <geometry>
            <plane>
              <normal>0 0 1</normal>
              <size>10 10</size>
            </plane>
          </geometry>
        </collision>
        <visual name="visual">
          <geometry>
            <plane>
              <normal>0 0 1</normal>
              <size>100 100</size>
            </plane>
          </geometry>
          <material>
            <ambient>0.8 0.8 0.8 1</ambient>
            <diffuse>0.8 0.8 0.8 1</diffuse>
            <specular>0.8 0.8 0.8 1</specular>
          </material>
        </visual>
      </link>
    </model>
    <model name='jumpRobot'>
      <link name="body_a">
        <!-- <pose>0 0 0.75 0 0 0</pose> -->
        <pose>0 0 0 0 0 0</pose>
        <self_collide>1</self_collide>
        <visual name="visual">
          <pose>0 0 0 0 0 0</pose>
          <geometry>
            <mesh>
              <uri>model://home/agd/jump_model/meshes/body.dae</uri>
            </mesh>
          </geometry>
          <material>
            <ambient>0.0 0.0 1.0 1</ambient>
            <diffuse>0.0 0.0 1.0 1</diffuse>
            <specular>0.0 0.0 1.0 1</specular>
          </material>
        </visual>
        <collision name="colision">
          <pose>0 0 0 0 0 0</pose>
          <geometry>
            <mesh>
              <uri>model://home/agd/jump_model/meshes/body.dae</uri>
            </mesh>
          </geometry>
        </collision>
        <inertial>
          <pose frame=''>0 0 0 0 0 0</pose>
          <mass>30.00</mass>
          <inertia>
            <ixx>0.038</ixx>
            <ixy>0</ixy>
            <ixz>0</ixz>
            <iyy>0.046</iyy>
            <iyz>0</iyz>
            <izz>0.022</izz>
          </inertia>
        </inertial>
      </link>
      <link name="upper_leg_a">
        <!-- <pose>0 0 0.625 0 0 0</pose> -->
        <pose>0 0 -0.125.75 0 0 0</pose>
        <self_collide>1</self_collide>
        <visual name="visual">
          <pose>0 0 0 0 0 0</pose>
          <geometry>
            <mesh>
              <uri>model://home/agd/jump_model/meshes/upper_leg.dae</uri>
            </mesh>
          </geometry>
          <material>
            <ambient>1.0 0.0 0.0 1</ambient>
            <diffuse>1.0 0.0 0.0 1</diffuse>
            <specular>1.0 0.0 0.0 1</specular>
          </material>
        </visual>
        <collision name="collision">
          <pose>0 0 0 0 0 0</pose>
          <geometry>
            <mesh>
              <uri>model://home/agd/jump_model/meshes/upper_leg.dae</uri>
            </mesh>
          </geometry>
        </collision>
        <inertial>
          <pose frame=''>0 0 -0.127 0 0 0</pose>
          <mass>1.50</mass>
          <inertia>
            <ixx>0</ixx>
            <ixy>0</ixy>
            <ixz>0</ixz>
            <iyy>6.8548e-04</iyy>
            <iyz>0</iyz>
            <izz>6.8548e-04</izz>
          </inertia>
        </inertial>
      </link>
      <link name="lower_leg_a">
        <!-- <pose>0 0 0.34 0 0 0</pose> -->
        <pose>0 0 -0.41 0 0 0</pose>
        <self_collide>1</self_collide>
        <visual name="visual">
          <pose>0 0 0 0 0 0</pose>
          <geometry>
            <mesh>
              <uri>model://home/agd/jump_model/meshes/lower_leg.dae</uri>
            </mesh>
          </geometry>
          <material>
            <ambient>0.0 1.0 0.0 1</ambient>
            <diffuse>0.0 1.0 0.0 1</diffuse>
            <specular>0.0 1.0 0.0 1</specular>
          </material>
        </visual>
        <collision name="collision">
          <pose>0 0 0 0 0 0</pose>
          <geometry>
            <mesh>
              <uri>model://home/agd/jump_model/meshes/lower_leg.dae</uri>
            </mesh>
          </geometry>
        </collision>
        <inertial>
          <pose frame=''>0 0 -0.105 0 0 0</pose>
          <mass>1.20</mass>
          <inertia>
            <ixx>0</ixx>
            <ixy>0</ixy>
            <ixz>0</ixz>
            <iyy>3.6750e-04</iyy>
            <iyz>0</iyz>
            <izz>3.6750e-04</izz>
          </inertia>
        </inertial>
      </link>
      <link name="foot">
        <!-- <pose>0 0 0.07 0 0 0</pose> -->
        <pose>0 0 -0.68 0 0 0</pose>
        <self_collide>1</self_collide>
        <visual name="visual">
          <pose>0 0 0 0 0 0</pose>
          <geometry>
            <mesh>
              <uri>model://home/agd/jump_model/meshes/foot.dae</uri>
            </mesh>
          </geometry>
          <!-- <material>
            <script>
              <uri>file://media/materials/scripts/gazebo.material</uri>
              <name>Gazebo/GreenTransparent</name>
            </script>
          </material> -->
        </visual>
        <collision name="foot_collision">
          <pose>0 0 0 0 0 0</pose>
          <geometry>
            <mesh>
              <uri>model://home/agd/jump_model/meshes/foot.dae</uri>
            </mesh>
          </geometry>
          <surface>
            <friction>
              <ode>
                <mu>0.9</mu>
                <mu2>0.9</mu2>
              </ode>
            </friction>
          </surface>
        </collision>
        <inertial>
          <pose frame=''>0 0 0 0 0 0</pose>
          <mass>0.1</mass>
          <inertia>
            <ixx>0</ixx>
            <ixy>0</ixy>
            <ixz>0</ixz>
            <iyy>0</iyy>
            <iyz>0</iyz>
            <izz>0</izz>
          </inertia>
        </inertial>
        <!-- <sensor name='sensor_contact' type='contact'>
          <contact>
            <collision>foot_collision</collision>
          </contact>
          <always_on>1</always_on>
        </sensor> -->
      </link>
      <joint name="base" type="prismatic">
        <parent>world</parent>
        <child>body_a</child>
        <axis>
          <xyz>0 0 1</xyz>
        </axis>
      </joint>
      <joint name="hfe" type="revolute">
        <pose>0 0 0 -1.570796326794896558 1.570796326794896558 0</pose>
        <parent>body_a</parent>
        <child>upper_leg_a</child>
        <axis>
          <xyz>0 0 1</xyz>
          <limit>
            <lower>-1.57</lower>
            <upper>1.57</upper>
            <!-- <velocity>100</velocity> -->
          </limit>
        </axis>
      </joint>
      <joint name="kfe" type="revolute">
        <pose>0 0 0 -1.570796326794896558 1.570796326794896558 0</pose>
        <parent>upper_leg_a</parent>
        <child>lower_leg_a</child>
        <axis>
          <xyz>0 0 1</xyz>
          <limit>
            <lower>-2.18</lower>
            <upper>2.18</upper>
            <!-- <velocity>100</velocity> -->
          </limit>
        </axis>
      </joint>
      <joint name="fft" type="fixed">
        <pose>0 0 0 -1.570796326794896558 1.570796326794896558 0</pose>
        <parent>lower_leg_a</parent>
        <child>foot</child>
        <sensor name="force_torque_sensor" type="force_torque">
          <always_on>true</always_on>
          <update_rate>100</update_rate>
          <visualize>true</visualize>
          <topic>/JumpRobot/foot/force_torque</topic>
          <force_torque>
            <frame>sensor</frame>
            <measure_direction>parent_to_child</measure_direction>
          </force_torque>
        </sensor>
      </joint>
      <plugin name="JumpController" 
        filename="/home/agd/jump_model/jump_rgc/build/libjump_controller.so">
        <joint_name>base</joint_name>
        <joint_name>hfe</joint_name>
        <joint_name>kfe</joint_name>
        <lc_update_rate>1000</lc_update_rate>
        <rgc_update_rate>100</rgc_update_rate>
      </plugin>
      <plugin name="gz::sim::systems::PythonSystemLoader"
        filename="gz-sim-python-system-loader-system">
        <module_name>jump_main</module_name>
      </plugin>
      <plugin name="gz::sim::systems::PythonSystemLoader"
        filename="gz-sim-python-system-loader-system">
        <module_name>jump_fgserver</module_name>
      </plugin>
      <!-- <plugin
        filename="gz-sim-contact-system"
        name="gz::sim::systems::Contact">
      </plugin> -->
      <plugin
        filename="gz-sim-forcetorque-system"
        name="gz::sim::systems::ForceTorque">
      </plugin>
      <!-- <plugin filename="gz-sim-touchplugin-system"
                    name="gz::sim::systems::TouchPlugin">
        <target>ground_plane</target>
        <namespace>JumpRobotTouchSensor</namespace>
        <time>0.001</time>
        <enabled>true</enabled>
      </plugin> -->
    </model>
  </world>
</sdf>